Workbook
Name ZZZ289: Test_Cases!$R$253:$DVH$289

Sheet Project_Info
A1: Project Name:
A2: Client:
A3: Created By:
A4: Creation Date:
A5: Reviewed by:
A6: Type of Testing:

Sheet Requirements
A1: Req_ID | B1: Description | C1: Type | D1: Priority | E1: Status | F1: Version
A2: REQ_LOGIN_01 | B2: System shall allow login with valid email and password | C2: Functional | D2: High | E2: Open
A3: REQ_LOGIN_02 | B3: System shall display warning after 10 minutes of inactivity | C3: Functional | D3: Medium | E3: Open
A4: REQ_LOGIN_03 | B4: System shall reject login with invalid or unregistered email | C4: Functional | D4: High | E4: Open
A5: REQ_LOGIN_04 | B5: System shall reject login with incorrect password | C5: Functional | D5: High | E5: Open
A6: REQ_LOGIN_05 | B6: System shall automatically logout user after inactivity | C6: Functional | D6: High | E6: Open
A7: REQ_LOGIN_06 | B7: System shall support auto login for returning users (Remember Me) | C7: Functional | D7: Medium | E7: Open
A8: REQ_LOGIN_07 | B8: System shall request phone/OTP verification after failed attempts | C8: Security | D8: High | E8: Open
A9: REQ_LOGIN_08 | B9: System shall validate empty email field | C9: Validation | D9: High | E9: Open
A10: REQ_LOGIN_09 | B10: System shall validate empty password field | C10: Validation | D10: High | E10: Open
A11: REQ_LOGIN_10 | B11: System shall treat password as case-sensitive | C11: Functional | D11: High | E11: Open
A12: REQ_LOGIN_11 | B12: System shall lock account after 5 failed login attempts | C12: Security | D12: Critical | E12: Open
A13: REQ_LOGIN_12 | B13: System shall provide "Forgot Password" functionality | C13: Functional | D13: High | E13: Open
... A22: REQ_LOGIN_21 | B22: System shall handle copy/paste securely in password field | C22: Security | D22: Low | E22: Open

Sheet Project_Plan
A1: Title | B1: Sprint Goal | C1: Plan
A2: Sprint 1 Duration (25/4 - 3/5) | B2: The goal of Sprint 1 is to prepare the complete QA environment, understand the OrangeHRM system, setup Agile tools, create the initial testing documentation, and prepare the project foundation for manual and automation testing. manual: Write User story , test cases, bug report and peer review by Manual team (Edit, Add, Delete) or upload as tickets for login page automation"

Sheet User_Stories
A1: US_ID | B1: UserStory | C1: Acceptance Criteria
B2: No of user stories | C2: =COUNTA(A:A)-1 -> 80
B3: No of Acceptance Criteria | C3: =COUNTA(C$4:C$1048576) -> 1065
A4: ="US_0" & COUNTA($A$1:A1) -> US_01 | B4: As an OrangeHRM user (Admin or ESS), I want to log in using my unique credentials, So that I can securely access my personal dashboard and HR management tools based on my assigned role. | C4: Scenario 1: User Authentication and Login Validation Given the user is on the Login page When the user enters login credentials and clicks the Login button Then the system should authenticate the user according to the provided credentials And When a valid username and password are entered Then the system should redirect the user to the appropriate Dashboard And When an invalid username or password is entered Then the system should deny access And display the generic error message "Invalid credentials" And should not indicate whether the username or password is incorrect And When the password is entered using incorrect letter casing Then the system should reject the login attempt And display the error message "Invalid credentials" And enforce password case sensitivity during authentication.
C5: Scenario 2: Validate Login Page UI Layout Given the user navigates to the Login page When the page loads successfully Then the system should display the required login components Including: Username Field Password Field Login Button OrangeHRM Logo And the Password field should mask entered characters by default And the Login button should be clearly visible and accessible And the OrangeHRM logo should be displayed correctly to maintain brand consistency.
C6: Scenario 3: Validate Login Security Requirements Given the user is on the Login page When the user attempts to log in Then the system should validate all required fields and display "Required" for any empty field(s) And When authentication is successful Then the system should maintain the user session until logout or session timeout And When invalid or malicious input is submitted Then the system should sanitize the input and prevent unauthorized access or security vulnerabilities.
C7: Scenario 4: Validate Login Edge Cases and Accessibility Given the user is on the Login page When five consecutive login attempts fail Then the system should temporarily lock the account for 20 minutes And When the user clicks "Forgot your password?" Then the system should redirect the user to the password reset request page And When the Login page is accessed from mobile, tablet, or desktop devices Then the login form should remain accessible, properly aligned, and fully functional across supported screen sizes.
C8: Scenario 5: Inactivity Warning Given the user is logged into the system, When the user remains inactive for a defined period (e.g., 10 minutes), Then the system should display a warning message indicating inactivity, And the session should remain active until further action or timeout occurs
C9: Scenario 6: Identity Verification After Failed Attempts Given the user enters incorrect login credentials multiple times, When the system detects suspicious or repeated failed attempts, Then the system should require additional identity verification (e.g., redirect to password reset or verification step), And prevent direct login without verification
C10: Scenario 7: Input Trimming Given the user enters username or password with leading or trailing spaces, When the login request is submitted, Then the system should trim unnecessary spaces before validation, And process the credentials correctly
C11: Scenario 8: Username Case Sensitivity Given the user enters the username with different letter cases, When the system processes the login request, Then the username should be treated as case-insensitive, And the user should be able to log in successfully if credentials are valid
C12: Scenario 9: Copy and Paste Behavior in Password Field Given the user is on the login page, When the user performs copy and paste actions in the password field, Then the system should allow paste functionality without breaking login behavior, And authentication should work as expected
C13: Scenario 10: CSRF Token Expiration Handling Given the user is on the login page and the session remains idle for a period of time, When the CSRF token expires and the user submits valid login credentials, Then the system should not block the user with a technical error message, And should display a clear, user-friendly message such as: "Session expired, please refresh the page", And allow the user to retry the login process successfully after refreshing the page
A15: ="US_0" & COUNTA($A$1:A14) -> US_02 | B15: As an OrangeHRM user who cannot remember my password, I want to request a password reset link by providing my username, So that I can securely regain access to my account without exposing my credentials. | C15: Scenario 1: Successful Password Reset Request Given the user is on the "Forgot your password?" page, When they enter a valid, registered username in the system, And they click the "Reset Password" button, Then the system should generate a secure, time-sensitive reset token, And send an email containing the reset link to the email address associated with that username, And redirect the user to a confirmation screen displaying: "Reset password link sent successfully".
C16: Scenario 2: Processing an Invalid Username (Account Harvesting Mitigation) Given the user is on the "Forgot your password?" page, When they enter a username that does not exist in the system, And they click the "Reset Password" button, Then the system should not send an email, And it must display the exact same confirmation screen: "Reset password link sent successfully". Note: This prevents malicious actors from guessing valid usernames based on different system responses
C17: Scenario 3: Input Field Validation Given the user is on the "Forgot your password?" page, When they leave the username field blank, And they click the "Reset Password" button, Then the system must prevent submission, And display a validation error message below the field stating: "Required".
C18: Scenario 4: Canceling the Reset Request Given the user is on the "Forgot your password?" page, When they click the "Cancel" button, Then the system should abort the request without sending an email, And redirect the user back to the primary Login page.
C19: Scenario 5: Rate Limiting on Reset Requests Given the user is on the Forgot Password page, When the same username submits multiple reset requests in a short period, Then the system should rate-limit subsequent requests, And display a message: 'Too many requests. Please try again later. | D19: added new
C20: Scenario 6: Token Expiry Given a password reset email has been sent, When the user clicks the reset link after the token has expired (e.g., after 24h), Then the system should display an error: 'This reset link has expired', And prompt the user to submit a new reset request. | D20: added new
A24: ="US_0" & COUNTA($A$1:A23) -> US_03 | B24: As a Logged-in Admin I want to view, add, search, edit, delete and manage employee records from the PIM page So that I can efficiently maintain accurate and up-to-date employee information within the organization. | C24: Scenario 1: Successful user creation Given I am logged in as Admin When I navigate to Admin → Add User And I fill all required fields correctly And click Save Then the system should create the user successfully And display a success message And the user should appear in the user list
C25: Scenario 2: Required fields validation Given I am on the Add User page When I click Save without filling required fields Then error messages should appear for: User Role Employee Name Username Password Confirm Password
C26: Scenario 3: Password mismatch Given I entered password and confirm password When they are different Then system should show: Passwords do not match
C27: Scenario 4: Username already exists Given I enter an existing username When I try to save Then system should show: Username already exists
C28: Scenario 5: Invalid employee name Given I enter an employee name not in system Then system should show validation error
C29: Scenario 6: Cancel action Given I click Cancel Then I should be redirected to user list page And no data should be saved
A31: ="US_0" & COUNTA($A$1:A30) -> US_04 | B31: As an Admin, I want to view, add, edit, and delete job titles, So that I can manage employee roles and organizational structure effectively. | C31: Scenario 1: View job titles list Given I am logged in as Admin When I navigate to Admin → Job Titles Then I should see a list of job titles And each row should display: Job Title Job Description Note And pagination should be available if needed
C32: Scenario 2: Add new job title Given I am on Job Titles page When I click Add And I enter valid job title details And click Save Then the job title should be added successfully And appear in the list
C33: Scenario 3: Required field validation Given I am adding a new job title When I leave required fields empty Then validation messages should appear
C34: Scenario 4: Edit job title Given I select an existing job title When I update its details And click Save Then changes should be saved successfully And reflected in the list
C35: Scenario 5: Delete job title (single) Given I select a job title When I click Delete And confirm deletion Then the job title should be removed from the list
C36: Scenario 6: Delete multiple job titles Given I select multiple job titles When I click Delete Selected And confirm Then all selected job titles should be deleted
C37: Scenario 7: Cancel delete Given I click delete When I cancel confirmation Then no job title should be deleted
C38: Scenario 8: Search / filter (if available) Given I enter search criteria When I click search Then filtered results should be displayed
C39: Scenario 9: No data case Given there are no job titles Then system should display: No Records Found
A41: ="US_0" & COUNTA($A$1:A40) -> US_05 | B41: As an Admin, I want to create, view, edit, and delete pay grades with salary ranges, So that I can define salary structures for employees in the organization. | C41: Scenario 1: View pay grades list Given I am logged in as Admin When I navigate to Admin → Pay Grades Then I should see a list of pay grades And each row should display: Pay Grade Name And pagination should work correctly
C42: Scenario 2: Add new pay grade Given I am on Pay Grades page When I click Add And I enter a valid pay grade name And click Save Then the pay grade should be created successfully And appear in the list
C43: Scenario 3: Required field validation Given I am adding a new pay grade When I leave the name empty Then the system should display a validation message
C44: Scenario 4: Edit pay grade Given I select an existing pay grade When I update the name And click Save Then the changes should be saved And reflected in the list
C45: Scenario 5: Delete pay grade (single) Given I select a pay grade When I click Delete And confirm Then the pay grade should be removed
C46: Scenario 6: Delete multiple pay grades Given I select multiple pay grades When I click Delete Selected Then all selected pay grades should be deleted
...

Sheet Test_Cases
A1: TC_ID | B1: Scenario | C1: AC ID | D1: Title | E1: Description | F1: Preconditions | G1: Test Steps | H1: Test Data | I1: Expected Result | J1: Postconditions | K1: Actual Result | L1: Status | M1: Author | N1: Automated | O1: Execution Cycle | P1: Priorty | Q1: Reviewed by | R1: Notes
A2: TC_LOGIN_001 | B2: Login | C2: AC_001 | D2: Verify successful login with valid Username and password | E2: Ensure that the user can log in successfully using valid registered email and password | F2: User is on login page | G2: 1. Enter valid username 2. Enter valid password 3. Click "Login" | H2: username: Admin Password: admin123 | I2: User logs in successfully and is redirected to the dashboard/home page | J2: User session is created and user is logged in | K2: User logged in successfully and redirected to dashboard | L2: Passed | M2: Afram | N2: Yes | O2: v1.0 | P2: Medium
A3: TC_LOGIN_002 | C3: AC_002 | D3: Verify system shows warning message after user inactivity (10 minutes) | E3: Ensure that the system detects user inactivity and displays a warning message after a defined idle time (e.g., 10 minutes) | F3: User is logged in | G3: 1. Login with valid email and password 2. Do not perform any action (no clicks / typing / scrolling) 3. Wait for 10 minutes | H3: username: Admin Password: admin123 | I3: System displays warning message like "You have been inactive for a while" | J3: Session is still active until user takes action | K3: No warning message displayed after 10 minutes | L3: Failed | M3: Afram | N3: Yes | P3: Medium | W3: Team member | X3: Test cases | Y3: Reviewed by
A4: TC_LOGIN_003 | C4: AC_003 | D4: Verify user is automatically logged out after inactivity warning | E4: Ensure system logs out user automatically if no action is taken after warning | F4: Warning message already displayed | G4: 1. Wait for warning message 2. Do not click anything 3. Wait additional 1–2 minutes | H4: username: Admin Password: admin123 | I4: User is automatically logged out and redirected to login page | J4: Session terminated | K4: User remains logged in | L4: Failed | M4: Afram | N4: Yes | P4: Critical | W4: Afram | X4: =COUNTIF(M:M, "Afram") -> 1025 | Y4: =COUNTIF(Q:Q, "Afram") -> 15
A5: TC_LOGIN_004 | C5: AC_004 | D5: Verify system handles expired CSRF token gracefully during login | E5: Ensure that when the CSRF token expires, the system provides a clear message or allows user to recover instead of blocking login abruptly | F5: Page has been idle for a period (token expiration) | G5: 1. Navigate to login page 2. Wait for a period of time (e.g., 5–10 minutes) 3. Enter valid username and password 4. Click "Login" | H5: Username: Admin Password: admin123 | I5: System should either: Allow login successfully, OR Display a user-friendly message like: "Session expired, please refresh the page" | J5: User can recover and proceed with login | K5: System displays "CSRF token validation failed" and blocks login | L5: Failed | M5: Afram | N5: Yes | P5: High | W5: AY | X5: =COUNTIF(M:M, "AY") -> 89 | Y5: =COUNTIF(Q:Q, "AY") -> 18
A6: TC_LOGIN_005 | C6: AC_005 | D6: Verify system requests identity verification after incorrect password attempts using username | E6: Ensure that if the user enters an incorrect password, the system allows the user to verify identity using their username to confirm account ownership | F6: User is registered with a valid username | G6: 1. Enter valid username 2. Enter incorrect password 3. Click "Login" 4. System prompts for identity verification 5. Confirm username / proceed with verification step 6. Submit | H6: Username: Admin Password: wrong123 | I6: System verifies user identity and allows password reset or secure login flow | J6: User proceeds to secure verification or password reset process | K6: System prompted for verification and allowed user to continue | L6: Passed | M6: Afram | N6: Yes | P6: High | W6: Omar | X6: =COUNTIF(M:M, "Omar") -> 310 | Y6: =COUNTIF(Q:Q, "Omar") -> 0
A7: TC_LOGIN_006 | C7: AC_006 | D7: Verify account lockout after 5 failed login attempts | E7: Ensure account is locked after multiple failed attempts | F7: User is registered | G7: 1. Enter valid username 2. Enter wrong password 3. Repeat 5 times 4. Try login again | H7: Username: Admin Password: wrong123 | I7: Account locked for 20 minutes + proper message | J7: User cannot login temporarily | K7: Account not locked | L7: Failed | M7: Afram | N7: Yes | P7: Critical | W7: Aly | X7: =COUNTIF(M:M, "Aly") -> 94 | Y7: =COUNTIF(Q:Q, "Aly") -> 0
A8: TC_LOGIN_007 | C8: AC_007 | D8: Verify "Forgot Password" link redirects correctly | E8: Ensure user can navigate to password reset page | F8: User is registered | G8: 1. Click "Forgot your password? | H8: User redirected to password reset page | I8: User is redirected to the password reset page | J8: Password reset page is displayed and user can initiate reset process | K8: User is successfully redirected to the password reset page | L8: Passed | M8: Afram | N8: Yes | P8: High | W8: Total | X8: =SUM(X4:X7) -> 1518
A9: TC_LOGIN_008 | C9: AC_008 | D9: Verify unauthorized users cannot access dashboard | E9: Ensure restricted pages are not accessible without authentication | F9: User is not logged in | G9: 1. Navigate directly to dashboard URL | H9: N/A | I9: User is redirected to login page | J9: Access is denied | K9: User successfully redirected to login page | L9: Passed | M9: Afram | N9: Yes | P9: Critical
A10: TC_LOGIN_009 | C10: AC_009 | D10: Verify user cannot access dashboard after logout using browser back button | E10: Ensure that after logging out, the user cannot navigate back to the dashboard using the browser back button and must be redirected to the login page | F10: User is on login page | G10: 1. Enter valid username and password 2. Click "Login" 3. Verify user is redirected to Dashboard 4. Click "Logout" 5. Click browser Back button | H10: Username: Admin Password: admin123 | I10: User should be redirected to the login page and not allowed to access the dashboard | J10: Session is terminated and protected pages are inaccessible | K10: User is able to access the dashboard after clicking back | L10: Failed | M10: Afram | N10: Yes | P10: High | W10: EXECUTION OVERVIEW
A11: TC_LOGIN_010 | C11: AC_010 | D11: Verify user cannot access dashboard using Back and Refresh after logout | E11: Ensure that after logout, using browser Back followed by Refresh does not allow access to the dashboard and always redirects to login page | F11: User is on login page | G11: 1. Enter valid username and password 2. Click "Login" 3. Verify user is redirected to Dashboard 4. Click browser Back button without "Logout" 5. Click browser Refresh (F5) | H11: Username: Admin Password: admin123 | I11: User should be redirected to login page and should not access dashboard | J11: Session is terminated and dashboard is inaccessible | K11: User is able to access dashboard after Back and Refresh without logging in | L11: Failed | M11: Afram | P11: High | W11: Test Cases Passed: | X11: =COUNTIF(L:L, "Passed") -> 1343
A12: TC_LOGIN_011 | C12: AC_011 | D12: Verify system prevents SQL injection | E12: Ensure inputs are sanitized against SQL injection | F12: User is on login page | G12: 1. Enter SQL injection payload in username 2. Enter any password 3. Click Login | H12: Username: ' OR 1=1 -- Password: any | I12: Login fails and input is sanitized | J12: System remains secure | K12: user has not logged in | L12: Passed | M12: Afram | P12: Critical | W12: Test Cases Failed: | X12: =COUNTIF(L:L, "Failed") -> 119
A13: TC_LOGIN_012 | C13: AC_012 | D13: Verify copy and paste behavior in password field | E13: Ensure system handles paste actions correctly in password field | F13: User is on login page | G13: 1. Copy password 2. Paste into password field 3. Click "Login" | H13: Username: Admin Password: admin123 | I13: The Password field should not accept the paste action | J13: User is logged in | K13: procedure of copying and pasting was successful | L13: Failed | M13: Afram | N13: Yes | P13: Low | W13: Total Test Cases Executed: | X13: =SUM(X11:X12) -> 1462
A14: TC_LOGIN_013 | C14: AC_013 | D14: Verify password field is masked | E14: Ensure password is hidden While writing | F14: User is on login page | G14: 1. Enter password | H14: Password: 123456 | I14: Password should be hidden (••••••) | J14: Password not visible | K14: Password masked by Eye icon toggle is successfully | L14: Passed | M14: Afram | N14: Yes | P14: High | W14: Automation
A15: TC_LOGIN_014 | C15: AC_014 | D15: Verify session persists after page refresh | E15: Ensure user remains logged in after refreshing the page | F15: User is logged in | G15: 1. Log in successfully 2. Refresh the page | H15: Username: Admin Password: admin123 | I15: User remains logged in | J15: Session remains active | K15: User is logged after refresh | L15: Passed | M15: Afram | N15: Yes | P15: High | W15: Automated | X15: =COUNTIF(N:N, "Yes") -> 710
A16: TC_LOGIN_015 | C16: AC_015 | D16: Verify login page responsiveness across devices | E16: Ensure login page works on mobile/tablet | F16: Open site on different screen sizes | G16: 1. Open on desktop 2. Open on tablet 3. Open on mobile | H16: N/A | I16: Layout adapts correctly on all devices | J16: Usable UI | K16: Layout successfully | L16: Passed | M16: Afram | N16: Yes | P16: High
A17: TC_LOGIN_016 | C17: AC_016 | D17: Verify login page UI elements are displayed correctly | E17: Ensure all required UI components are visible | F17: User is on login page | G17: 1. Check presence of username field 2. Check password field 3. Check login button 4. Check logo | H17: N/A | I17: All UI elements displayed correctly | J17: UI ready for interaction | K17: elements displayed correctly | L17: Passed | M17: Afram | N17: Yes | P17: Medium | W17: Test Case priorties
A18: TC_LOGIN_017 | C18: AC_017 | D18: Verify whether username field is case-sensitive | E18: Ensure system behavior when entering username in different letter cases | F18: User is on login page | G18: 1. Enter username: admin 2. Enter valid password 3. Click "Login" | H18: Username: admin (actual: Admin) Password: admin123 | I18: Login fails (case-sensitive username) | J18: User logged in or access denied based on system behavior | K18: User logged in successfully | L18: Failed | M18: Afram | N18: Yes | P18: High | W18: Critical | X18: =COUNTIF(P:P, "Critical") -> 94
A19: TC_LOGIN_018 | C19: AC_018 | D19: Verify password is case-sensitive | E19: Ensure that login fails when password case is incorrect | F19: User is registered | G19: 1. Enter valid username 2. Enter correct password but with different case 3. Click "Login" | H19: Username: Admin Password: Admin123 (actual: admin123) | I19: Login should fail with "Invalid credentials" | J19: User not logged in | K19: user has not logged in | L19: Passed | M19: Afram | N19: Yes | P19: High | W19: High | X19: =COUNTIF(P:P, "High") -> 722
A20: TC_LOGIN_019 | C20: AC_019 | D20: Verify system trims leading and trailing spaces in input fields | E20: Ensure spaces before and after input values are ignored | F20: User is registered | G20: 1. Enter username with leading and trailing spaces 2. Enter valid password 3. Click "Login" | H20: Username: " Admin " Password: admin123 | I20: Login failed due to spaces | J20: User is logged in | K20: Login CSRF token validation failed | L20: Passed | M20: Afram | N20: Yes | P20: Medium | R20: Delete | W20: Medium | X20: =COUNTIF(P:P, "Medium") -> 460
A21: TC_LOGIN_020 | C21: AC_020 | D21: Verify login fails with invalid username | E21: Ensure that the system does not allow login with an unregistered or invalid username | F21: User is on login page | G21: 1. Enter Invalid email 2. Enter valid password 3. Click "Login" | H21: username: wrong Password: admin123 | I21: Error message "Invalid username or password" is displayed | J21: User is not logged in | K21: User is not logged in | L21: Passed | M21: Afram | N21: Yes | P21: High | W21: Low | X21: =COUNTIF(P:P, "Low") -> 84
A22: TC_LOGIN_021 | C22: AC_021 | D22: Verify login fails with incorrect password | E22: Ensure that the system rejects login when password is incorrect | F22: User is on login page | G22: 1. Enter valid email 2. Enter Wrong password 3. Click "Login" | H22: username: Admin Password: wrong123 | I22: Error message "Invalid username or password" is displayed | J22: User is not logged in | K22: User is not logged in | L22: Passed | M22: Afram | N22: Yes | P22: High
A23: TC_LOGIN_022 | C23: AC_022 | D23: Verify validation when username field is empty | E23: Ensure system shows validation when username is empty | F23: User is on login page | G23: 1. Leave email empty 2. Enter password 3. Click "Login" | H23: username: Password: admin123 | I23: "username is required" message displayed | J23: Login blocked | K23: validation message shown | L23: Passed | M23: Afram | N23: Yes | P23: High
A24: TC_LOGIN_023 | C24: AC_023 | D24: Verify validation when password field is empty | E24: Ensure system shows validation when password is empty | F24: User is on login page | G24: 1. Enter email 2. Leave password empty 3. Click "Login" | H24: username: Admin Password: | I24: "Password is required" message displayed | J24: Login blocked | K24: validation message shown | L24: Passed | M24: Afram | N24: Yes | P24: High
A25: TC_LOGIN_024 | C25: AC_024 | D25: Verify login with Enter key | E25: Ensure user can submit login by pressing Enter | F25: User is on login page | G25: 1. Enter valid username 2. Enter valid password 3. Press Enter key | H25: Username: Admin Password: admin123 | I25: User logs in successfully | J25: User session created | K25: User logged in successfully | L25: Passed | M25: Omar | N25: Yes | P25: Medium | Q25: Afram
A26: TC_LOGIN_025 | C26: AC_025 | D26: Verify login with both fields empty | E26: Ensure validation for both empty fields | F26: User is on login page | G26: 1. Leave username empty 2. Leave password empty 3. Click Login | H26: Username: Password: | I26: "Required" shown under both fields | J26: Login blocked | K26: Required messages shown | L26: Passed | M26: Omar | N26: Yes | P26: High | Q26: Afram
A27: TC_LOGIN_026 | C27: AC_026 | D27: Verify login button is disabled during processing | E27: Ensure double-click prevention during login | F27: User is on login page | G27: 1. Enter valid credentials 2. Click Login rapidly twice | H27: Username: Admin Password: admin123 | I27: Only one login request processed | J27: Single session created | K27: Button allows multiple clicks | L27: Failed | M27: Omar | N27: Yes | P27: Medium | Q27: Afram
A28: TC_LOGIN_027 | C28: AC_027 | D28: Verify password field toggle visibility | E28: Ensure eye icon toggles password visibility | F28: User is on login page | G28: 1. Enter password 2. Click eye icon to show 3. Click again to hide | H28: Password: admin123 | I28: Password toggles between masked and visible | J28: Password display changes | K28: Toggle works correctly | L28: Passed | M28: Omar | N28: Yes | P28: Low | Q28: Afram
A29: TC_LOGIN_028 | C29: AC_028 | D29: Verify footer links and social media icons | E29: Ensure all footer elements are functional | F29: User is on login page | G29: 1. Check copyright text 2. Click OrangeHRM link 3. Click each social media icon | H29: N/A | I29: All links open correct pages in new tabs | J29: Footer elements verified | K29: All links work correctly | L29: Passed | M29: Omar | N29: Yes | P29: Medium | Q29: Afram
A30: TC_LOGIN_029 | C30: AC_031 | D30: Verify login with both fields invalid | E30: Ensure that the user cann't log in successfully using invalid email and password | F30: User is on login page | G30: 1. Enter invalid email 2. Enter invalid password 3. Click "Login" | H30: Email: notadmin Password: wrong123 | I30: login failed | J30: User proceeds to secure verification or password reset process | K30: User failed to log in successfully and redirect to dashboard | L30: Passed | M30: Omar | N30: Yes | P30: High | Q30: Afram
A31: TC_LOGIN_030 | C31: AC_032 | D31: Verfiy double-click login bypass with invalid password | E31: When a user enters a valid username and an incorrect password, clicking the Login button twice in quick succession bypasses authentication and grants access to the dashboard | F31: 1. Browser is open and navigated to the OrangeHRM login page. 2. No user is currently logged in. 3. Login page is fully loaded. | G31: 1. Navigate to https://opensource-demo.orangehrmlive.com/ 2. Enter a valid username in the Username field. 3. Enter an incorrect password in the Password field. 4. Rapidly click the "Login" button two times in quick succession. 5. Observe the application behavior and the page navigated to. | H31: Username: Admin Password: WrongPassword123! | I31: The system should display an "Invalid credentials" error message and remain on the login page. The user should NOT be authenticated or redirected to the Dashboard. | J31: User remains on the login page. No session or authentication token is created. | K31: The system authenticates the user and redirects to the Dashboard page despite the incorrect password being entered. Login is successful after the second click. | L31: Failed | M31: Omar | P31: Critical | Q31: Afram
A32: TC_LOGIN_031 | C32: AC_033 | D32: Login credentials persist in fields after logout | E32: After a user logs out of the application, the login page fields (Username and Password) still retain the previously entered credentials instead of being cleared. This is a security vulnerability as it exposes credentials to the next user of the same browser session. | F32: 1. User is currently logged into the OrangeHRM application with valid credentials. 2. The dashboard or any internal page is displayed. | G32: 1. Login to the application using valid credentials (Username and Password). 2. Verify successful login (Dashboard is displayed). 3. Click on the user profile dropdown in the top-right corner. 4. Click the "Logout" option. 5. Observe the login page after being redirected. 6. Check the Username and Password fields for any pre-filled values. | H32: Username: Admin Password: admin123 | I32: After logout, the login page should be displayed with both the Username and Password fields completely empty/cleared. No previously entered credentials should be visible or pre-filled. | J32: User is redirected to a clean login page with empty Username and Password fields. No session data or cached credentials remain. | K32: After logout, the login page is displayed but the Username and Password fields still contain the previously entered credentials (Admin / admin123). The fields are not cleared upon logout. | L32: Failed | M32: Omar | P32: High | Q32: Afram
A33: TC_LOGIN_032 | D33: Verify login page title is correct in browser tab | E33: Ensure the browser tab displays the correct page title for the login page | F33: User navigates to login page URL | G33: 1. Open https://opensource-demo.orangehrmlive.com/web/index.php/auth/login 2. Check the browser tab title | H33: N/A | I33: Browser tab title should display 'OrangeHRM' | J33: Login page is loaded | K33: Displayed Successfully | L33: Passed | M33: Omar | N33: Yes | P33: Low
A34: TC_LOGIN_033 | D34: Verify login page displays OrangeHRM logo and tagline | E34: Ensure the OrangeHRM logo and tagline 'Wow Factor' are visible on the login page | F34: User is on login page | G34: 1. Navigate to login page 2. Visually inspect logo area 3. Check for tagline text | H34: N/A | I34: OrangeHRM logo and tagline 'Wow Factor' are displayed correctly | J34: Login page loaded | K34: OrangeHRM logo (ohrm_logo.png) and branding image (ohrm_branding.png) are both visible on the login page. | L34: Passed | M34: Omar | N34: Yes | P34: Low
A35: TC_LOGIN_034 | D35: Verify Tab key navigates between Username and Password fields | E35: Ensure keyboard Tab key moves focus from Username to Password to Login button | F35: User is on login page | G35: 1. Click on Username field 2. Press Tab key 3. Observe focus moves to Password 4. Press Tab again 5. Observe focus moves to Login button | H35: N/A | I35: Focus moves: Username → Password → Login button in correct order | J35: Login page loaded | K35: Tab key from Username field correctly moves focus to the Password field (placeholder='Password' confirmed as focused element). | L35: Passed | M35: Omar | N35: Yes | P35: Medium
A36: TC_LOGIN_035 | D36: Verify login with username containing only spaces | E36: Ensure login fails when username contains only whitespace characters | F36: User is on login page | G36: 1. Enter ' ' (spaces only) in username 2. Enter valid password 3. Click Login | H36: Username: ' ' (3 spaces) Password: admin123 | I36: Required' validation message is displayed OR login fails with 'Invalid credentials' | J36: No session created | K36: Login attempt with username containing only spaces (' ') is blocked. 'Required' validation message is displayed. No session created. | L36: Passed | M36: Omar | N36: Yes | P36: Medium
A37: TC_LOGIN_036 | D37: Verify login with password containing only spaces | E37: Ensure login fails when password contains only whitespace characters | F37: User is on login page | G37: 1. Enter 'Admin' in username 2. Enter ' ' (spaces only) in password 3. Click Login | H37: Username: Admin Password: ' ' (3 spaces) | I37: Required' validation message OR 'Invalid credentials' error displayed | J37: No session created | K37: Login attempt with password containing only spaces (' ') is blocked. 'Required' validation message is displayed. No session created. | L37: Passed | M37: Omar | N37: Yes | P37: Medium
A38: TC_LOGIN_037 | D38: Verify login with very long username (boundary test) | E38: Ensure system handles excessively long username input gracefully | F38: User is on login page | G38: 1. Enter 256-character string in username field 2. Enter valid password 3. Click Login | H38: Username: 'A' * 256 Password: admin123 | I38: System either truncates input or displays appropriate validation error. No crash. | J38: No crash or server error | K38: System accepts 256-character username input without truncation. No server crash or 500 error. Login fails with 'Invalid credentials' as expected. | L38: Passed | M38: Omar | N38: Yes | P38: Medium
A39: TC_LOGIN_038 | D39: Verify login with very long password (boundary test) | E39: Ensure system handles excessively long password input gracefully | F39: User is on login page | G39: 1. Enter valid username 2. Enter 256-character string in password field 3. Click Login | H39: Username: Admin Password: 'a' * 256 | I39: System either truncates input or displays 'Invalid credentials'. No crash or server error. | J39: No crash | K39: System accepts 256-character password input without truncation. No server crash or 500 error. Login fails with 'Invalid credentials' as expected. | L39: Passed | M39: Omar | N39: Yes | P39: Medium
A40: TC_LOGIN_039 | D40: Verify password field does not show password in page source | E40: Ensure password input is of type='password' and not exposed in HTML source | F40: User is on login page | G40: 1. Right-click on password field 2. Select Inspect Element 3. Check input type attribute | H40: N/A | I40: Password field input type is 'password', not 'text' | J40: Login page loaded | K40: Password field HTML type attribute = 'password'. Input is correctly masked. Characters are not exposed as plain text. | L40: Passed | M40: Omar | N40: Yes | P40: High
...

Sheet Bug_Report
A1: Bug ID | B1: Module / Feature | C1: Title / Summary | D1: Reported By | E1: Detected In / Test Cycle | F1: Severity | G1: Environment | H1: TC_ID | I1: Req_ID/US_ID | J1: Description | K1: Steps to Reproduce | L1: Expected Result | M1: Actual Result | N1: Attachments / Evidence | O1: Status | P1: Assigned To | Q1: Detected By | R1: Date Logged | S1: Comments / Root Cause
A2: Bug_001 | B2: Login | C2: Warning message not displayed after 10 minutes of inactivity | D2: AY | F2: Medium | G2: Edge Browser - Windows 10 / 11 - Android 14 | H2: TC_LOGIN_002 | J2: The system fails to detect user inactivity and does not trigger the mandatory warning message after the 10-minute idle threshold. | K2: 1. Login with valid email and password 2. Do not perform any action (no clicks / typing / scrolling) 3. Wait for 10 minutes | L2: System displays warning message like "You have been inactive for a while" | M2: No warning message displayed after 10 minutes | O2: Open | Q2: Afram
A3: Bug_002 | B3: Login | C3: Verify user is automatically logged out after inactivity warning | D3: AY | F3: Critical | G3: Edge Browser - Windows 10 / 11 - Android 14 | H3: TC_LOGIN_003 | J3: The system fails to automatically log out the user and redirect them to the login page when no action is taken after the inactivity warning is displayed | K3: 1. Wait for warning message 2. Do not click anything 3. Wait additional 1–2 minutes | L3: User is automatically logged out and redirected to login page | M3: User remains logged in | O3: Open | Q3: Afram
A4: Bug_003 | B4: Login | C4: CSRF token validation failed during idle login | D4: Omar | F4: High | G4: Edge Browser - Windows 10 / 11 - Android 14 | H4: TC_LOGIN_004 | J4: Login fails with CSRF token error after page sits idle, blocking user from authenticating. | K4: 1. Open login page 2. Wait 5-10 minutes 3. Enter valid credentials 4. Click Login | L4: Login succeeds or user-friendly message shown | M4: System shows "CSRF token validation failed" | N4: https://drive.google.com/open?id=1iaIQ9FdLIvMj0pNKl406TaBExVOTQW0M&usp=drive_copy | O4: Open | P4: Omar | Q4: Omar | S4: Root cause: CSRF token has short TTL. Application does not auto-refresh token or handle token expiry gracefully. Fix: Implement silent token refresh on form submit or display a user-friendly 'session expired' message with a 'Refresh' button.
A5: Bug_004 | B5: Login | C5: Account lockout not triggered after 5 failed login attempts | D5: AY | F5: High | G5: Edge Browser - Windows 10 / 11 - Android 14 | H5: TC_LOGIN_006 | J5: The system fails to enforce security protocols by not locking the account after the maximum allowed failed login attempts. | K5: 1. Enter a valid registered username (e.g., "Admin"). 2. Enter an incorrect password (e.g., "wrong123"). 3. Repeat the login attempt 5 times. 4. Attempt to log in again. | L5: Account locked for 20 minutes + proper message | M5: Account not locked | O5: Open | Q5: Afram
A6: Bug_005 | B6: Login | C6: Dashboard remains accessible via browser back button after logout | D6: AY | F6: High | G6: Edge Browser - Windows 10 / 11 - Android 14 | H6: TC_LOGIN_009 | J6: After logging out, the system fails to prevent the user from navigating back to the dashboard using the browser's back button. | K6: 1. Ensure the user is not logged in. 2. Navigate directly to the dashboard URL. | L6: User is redirected to login page | M6: User accessed the page | O6: Open | Q6: Afram | T6: ######
A7: Bug_006 | B7: Login | C7: Dashboard remains accessible via Browser Back and Refresh after logout | D7: AY | F7: High | G7: Edge Browser - Windows 10 / 11 - Android 14 | H7: TC_LOGIN_010 | J7: The application fails to properly invalidate the session or clear cache, allowing a user to bypass authentication by navigating back from the dashboard to login page and refreshing the page after logging out. | K7: 1. Enter valid username and password 2. Click "Login" 3. Verify user is redirected to Dashboard 4. Click browser Back button without "Logout" 5. Click browser Refresh (F5) | L7: Session is terminated and dashboard is inaccessible | M7: User is able to access dashboard after Back and Refresh without logging in | N7: https://drive.google.com/open?id=1R8wzKEIy2DvoaLllUSkf32SqBYssERaM&usp=drive_copy | O7: Open | Q7: Afram
A8: Bug_007 | C8: Password field accepts paste actions contrary to security requirements | D8: AY | F8: Low | G8: Edge Browser - Windows 10 / 11 - Android 14 | H8: TC_LOGIN_012 | J8: The password field accepts programmatic clipboard paste actions, failing to restrict pasting sensitive credential data as expected. | K8: 1. Navigate to the login page. 2. Copy the correct password ("admin123"). 3. Paste the password into the password field. 4. Enter the username ("Admin"). 5. Click "Login". | L8: The password field should not accept the paste action | M8: The password field should not accept the paste action | O8: Open | Q8: Afram | S8: The clipboard paste restriction is missing or not properly enforced on the password input element.
A9: Bug_008 | B9: Login | C9: Username field is not case-sensitive | D9: AY | F9: High | G9: Edge Browser - Windows 10 / 11 - Android 14 | H9: TC_LOGIN_017 | J9: The system fails to enforce case-sensitivity for usernames during the login process. It allows successful authentication even when the letter casing does not match the registered account details. | K9: 1. Navigate to the login page. 2. Enter a valid username in lowercase (e.g., "admin") where the actual registered username is capitalized (e.g., "Admin"). 3. Enter the correct password ("admin123"). 4. Click the "Login" button. | L9: Login should fail and access should be denied based on a case-sensitive authentication requirement. | M9: User logged in successfully | O9: Open | Q9: Afram
A10: Bug_009 | B10: Login | C10: Login button allows multiple rapid clicks during authentication | D10: Omar | F10: Medium | G10: Edge Browser - Windows 10 / 11 - Android 14 | H10: TC_LOGIN_026 | J10: Login button is not disabled during authentication processing, allowing multiple rapid clicks which could trigger duplicate requests. | K10: 1. Open login page 2. Enter valid credentials 3. Rapidly click Login button multiple times | L10: Button disabled after first click, single request processed | M10: Multiple login requests sent | O10: Open | P10: Omar | Q10: Omar | S10: Root cause: Missing client-side submission state handling, allowing rapid successive POST requests to the authentication endpoint. Fix: Disable the login button and display a loading indicator immediately upon the first click, re-enabling it only if the authentication request fails.
A11: Bug_010 | B11: Login | C11: Spaces in username cause CSRF token error instead of proper validation | D11: Omar | G11: Edge Browser - Windows 10 / 11 - Android 14 | J11: Entering username with leading/trailing spaces triggers a CSRF token validation error instead of trimming or showing a proper validation message. | K11: 1. Open login page 2. Enter " Admin " (with spaces) 3. Enter valid password 4. Click Login | L11: System trims spaces and processes login normally | M11: CSRF token validation failed error | O11: Open | P11: Omar | Q11: Omar | S11: Root cause: CSRF token validation relies on a strict payload hash that breaks when unexpected whitespace alters the request body before the validation middleware runs. Fix: Apply input sanitization middleware to strip leading and trailing whitespace from the payload before CSRF hashing and validation occur.
A12: Bug_011 | B12: Login | C12: Login button is not disabled during processing - allows multiple clicks and duplicate login requests | D12: Omar | G12: Edge Browser - Windows 10 / 11 - Android 14 | H12: متكررة هي هي 8 | J12: When a user enters valid credentials and rapidly clicks the Login button twice, the button does not become disabled during the authentication processing. This allows multiple login requests to be sent to the server simultaneously, potentially creating multiple sessions instead of a single session. The login button should be disabled immediately after the first click to prevent duplicate submissions. | K12: 1. Navigate to https://opensource-demo.orangehrmlive.com/ 2. Enter valid credentials in the Username and Password fields. 3. Click the "Login" button rapidly twice in quick succession. 4. Observe the button state and the number of requests sent. | L12: Only one login request should be processed. The Login button should be disabled/show a loading state after the first click, preventing duplicate submissions. A single session should be created. | M12: The Login button allows multiple clicks. Multiple login requests are sent to the server. No loading state or disabled state is applied to the button during authentication processing. | O12: Open | P12: Omar | Q12: Omar | S12: Root cause: Missing client-side submission state handling, allowing rapid successive POST requests to the authentication endpoint. Fix: Disable the login button and display a loading indicator immediately upon the first click, re-enabling it only if the authentication request fails. | T12: متكررة هي هي 8
A13: Bug_012 | B13: Login | C13: Double-click login bypass with invalid password - clicking Login twice with wrong password grants unauthorized dashboard access | D13: Omar | F13: Critical | G13: Edge Browser - Windows 10 / 11 - Android 14 | H13: TC_LOGIN_030 | J13: When a user enters a valid username and an incorrect password, clicking the Login button twice in quick succession bypasses authentication and grants access to the dashboard. This is a critical authentication bypass vulnerability that allows unauthorized access to the system with only knowledge of a valid username. The server appears to process the second request before fully validating the first, resulting in a race condition that circumvents password verification. | K13: 1. Navigate to https://opensource-demo.orangehrmlive.com/ 2. Enter a valid username in the Username field. 3. Enter an incorrect password in the Password field. 4. Rapidly click the "Login" button two times in quick succession. 5. Observe the application behavior and the page navigated to. | L13: The system should display an "Invalid credentials" error message and remain on the login page. The user should NOT be authenticated or redirected to the Dashboard. No session or authentication token should be created. | M13: The system authenticates the user and redirects to the Dashboard page despite the incorrect password being entered. Login is successful after the second click. A valid session is created, granting full access to the application. | O13: Open | P13: Omar | Q13: Omar | S13: Root cause: Time-of-Check to Time-of-Use (TOCTOU) race condition in the backend authentication controller where overlapping requests exploit uninitialized session states. Fix: Implement strict backend thread-safety for session creation, enforce rate-limiting on the login endpoint, and ensure atomic transaction handling for all authentication checks. | T13: مش بيدخل معايا عادي فهل دي bug؟
A14: Bug_013 | B14: Login | C14: Login credentials persist in Username and Password fields after user logs out of the application | D14: Omar | F14: High | G14: Edge Browser - Windows 10 / 11 - Android 14 | H14: TC_LOGIN_031 | J14: After a user logs out of the application, the login page fields (Username and Password) still retain the previously entered credentials instead of being cleared. This is a security vulnerability as it exposes user credentials to the next person who uses the same browser session, particularly on shared or public workstations. | K14: 1. Navigate to https://opensource-demo.orangehrmlive.com/ 2. Login to the application using valid credentials (Username and Password). 3. Verify successful login (Dashboard is displayed). 4. Click on the user profile dropdown in the top-right corner. 5. Click the "Logout" option. 6. Observe the login page after being redirected. 7. Check the Username and Password fields for any pre-filled values. | L14: After logout, the login page should be displayed with both the Username and Password fields completely empty/cleared. No previously entered credentials should be visible or pre-filled in any field. | M14: After logout, the login page is displayed but the Username and Password fields still contain the previously entered credentials (Admin / admin123). The fields are not cleared upon logout. The credentials are fully visible and usable by anyone who accesses the browser. | O14: Open | P14: Omar | Q14: Omar | S14: Root cause: The logout handler successfully destroys the server-side session but relies on a soft client-side redirect without clearing the DOM state or browser cache. Fix: Clear local component state upon logout, force a hard redirect or page reload, and add autocomplete="off" to sensitive form fields. | T14: دي حاجة من الـ browser اما لو جربتها في icoginato هتلاقي مفيش حاجة مكتوبة
A15: Bug_025 | B15: Login – Security | C15: Password field missing 'autocomplete' attribute — browser may autofill or save password without restriction | D15: Omar | F15: Medium | G15: Edge Browser - Windows 10 / 11 - Android 14 | H15: TC_LOGIN_043 | J15: The password input field on the Login page does not have an 'autocomplete' attribute set. Without autocomplete='off' or autocomplete='current-password', browsers may offer to save the password and autofill it on subsequent visits. On shared or public workstations, browser-saved credentials could expose a user's password to anyone who uses the same browser profile. | K15: 1. Navigate to the Login page. 2. Right-click on the Password field. 3. Select 'Inspect Element' (or 'Inspect'). 4. Examine the <input> element in the HTML inspector. 5. Look for the 'autocomplete' attribute. | L15: Password field has attribute: autocomplete='off' OR autocomplete='current-password'. Browser does not offer to save or autofill the password automatically. | M15: Password field has NO autocomplete attribute (value = None / attribute absent). Browser may offer to save and autofill the password. On shared devices, saved passwords could be accessible to subsequent users. | O15: Open | P15: Omar | Q15: Omar | S15: Root cause: 501 error indicates a server-side handler is not implemented or not configured for the Admin account's reset flow. This may be specific to the Admin account type which may require a different reset mechanism. Verify whether Admin accounts should use the standard reset flow or a separate process.
A16: Bug_014 | B16: Login | C16: System fails to trim leading spaces in username input field | D16: Omar | F16: Medium | G16: Edge Browser - Windows 10 / 11 - Android 14 | H16: TC_LOGIN_047 | J16: When a user enters a username with leading spaces (e.g., ' Admin'), the system does not trim the whitespace before authentication. This causes the login to fail even though the core username value is valid. The system should automatically strip leading whitespace from the username field before processing the login request. | K16: 1. Navigate to the OrangeHRM login page. 2. Enter username with leading spaces: ' Admin' (space before Admin). 3. Enter valid password: 'admin123'. 4. Click the 'Login' button. | L16: Leading spaces are trimmed from the username, and the user is logged in successfully. | M16: Login failed. The system did not trim the leading spaces and treated ' Admin' as an invalid username. | O16: Open | P16: Omar | Q16: Omar | S16: Root cause: Both the front-end form submission and back-end authentication controllers lack basic input sanitization, passing raw strings with whitespace directly into the validation logic. Fix: Implement .trim() on the front-end inputs before submission, and enforce identical trimming middleware on the back-end before querying the database.
A17: Bug_015 | B17: Login | C17: System fails to trim leading spaces in password input field | D17: Omar | F17: Medium | G17: Edge Browser - Windows 10 / 11 - Android 14 | H17: TC_LOGIN_049 | J17: When a user enters a password with leading spaces (e.g., ' admin123'), the system does not trim the whitespace before authentication. This causes the login to fail even though the core password value is correct. The system should automatically strip leading whitespace from the password field before processing the login request. | K17: 1. Navigate to the OrangeHRM login page. 2. Enter valid username: 'Admin'. 3. Enter password with leading spaces: ' admin123' (spaces before admin123). 4. Click the 'Login' button. | L17: Leading spaces are trimmed from the password, and the user is logged in successfully. | M17: Login failed. The system did not trim the leading spaces and treated ' admin123' as an invalid password. | O17: Open | P17: Omar | Q17: Omar | S17: Root cause: Both the front-end form submission and back-end authentication controllers lack basic input sanitization, passing raw strings with whitespace directly into the validation logic. Fix: Implement .trim() on the front-end inputs before submission, and enforce identical trimming middleware on the back-end before querying the database.
A18: Bug_016 | B18: Login | C18: System fails to trim trailing spaces in password input field | D18: Omar | F18: Medium | G18: Edge Browser - Windows 10 / 11 - Android 14 | H18: TC_LOGIN_050 | J18: When a user enters a password with trailing spaces (e.g., 'admin123 '), the system does not trim the whitespace before authentication. This causes the login to fail even though the core password value is correct. The system should automatically strip trailing whitespace from the password field before processing the login request. | K18: 1. Navigate to the OrangeHRM login page. 2. Enter valid username: 'Admin'. 3. Enter password with trailing spaces: 'admin123 ' (spaces after admin123). 4. Click the 'Login' button. | L18: Trailing spaces are trimmed from the password, and the user is logged in successfully. | M18: Login failed. The system did not trim the trailing spaces and treated 'admin123 ' as an invalid password. | O18: Open | P18: Omar | Q18: Omar | S18: Root cause: Both the front-end form submission and back-end authentication controllers lack basic input sanitization, passing raw strings with whitespace directly into the validation logic. Fix: Implement .trim() on the front-end inputs before submission, and enforce identical trimming middleware on the back-end before querying the database.
A19: Bug_017 | B19: Forgot Password – Server Error | C19: Password reset request for 'Admin' returns 501 Not Implemented server error — reset workflow blocked | D19: Omar | F19: Critical | G19: Edge Browser - Windows 10 / 11 - Android 14 | H19: TC_LOGIN_055 | J19: When the 'Admin' username is submitted on the Forgot Password page, the server returns an HTTP 501 Not Implemented error instead of processing the request and displaying the confirmation page. The reset workflow is completely broken for the Admin account. The page hangs for several seconds before displaying the 501 error, and no confirmation or reset link is generated. | K19: 1. Navigate to the Forgot Password page. 2. Enter username: Admin. 3. Click 'Reset Password'. 4. Wait for the system response. 5. Observe the page displayed after submission. | L19: System processes the reset request and redirects to confirmation page displaying: 'Reset password link sent successfully. If the email does not arrive, please contact your OrangeHRM Administrator.' | M19: System loads for 5–8 seconds, then displays a 501 Not Implemented HTTP error page. No confirmation message is shown. No reset link is generated. The Admin password reset is completely non-functional. | O19: Open | Q19: Omar | S19: Root cause: 501 error indicates a server-side handler is not implemented or not configured for the Admin account's reset flow. This may be specific to the Admin account type which may require a different reset mechanism. Verify whether Admin accounts should use the standard reset flow or a separate process.
A20: Bug_018 | B20: Forgot Password – Email Delivery | C20: Password reset email is not delivered — system shows 'contact administrator' message instead of email | D20: Omar | F20: High | G20: Edge Browser - Windows 10 / 11 - Android 14 | H20: TC_LOGIN_059 | J20: After submitting a valid password reset request on the Forgot Password page, the system displays: 'If the email does not arrive, please contact your OrangeHRM Administrator.' No reset email is received in the user's inbox (including spam/junk). The password recovery feature is non-functional — users who forget their password cannot reset it through the self-service flow. | K20: 1. Navigate to the Forgot Password page. 2. Enter a valid registered username (e.g., afram). 3. Click 'Reset Password'. 4. Note the confirmation message displayed. 5. Check the email inbox associated with the user account. 6. Check spam/junk folder. 7. Wait 5 minutes and check again. | L20: Reset email is delivered to the user's email address within 2–5 minutes. Email contains a secure, time-limited password reset link. User can click the link to set a new password. | M20: No reset email is received in any folder (inbox, spam, junk). System only shows: 'If the email does not arrive, please contact your OrangeHRM Administrator.' The reset link is never generated or delivered. | O20: Open | Q20: Omar
A21: Bug_019 | B21: Forgot Password – UI Behavior | C21: Reset Password' button remains active during processing — allows multiple submissions of the same reset request | D21: Omar | G21: Edge Browser - Windows 10 / 11 - Android 14 | H21: TC_LOGIN_060 | J21: After clicking the 'Reset Password' button on the Forgot Password page, the button remains fully clickable during the server processing period. Users can click the button multiple times in rapid succession, potentially sending multiple duplicate reset requests to the server. No loading state, disabled state, or visual feedback is shown to indicate the request is being processed. | K21: 1. Navigate to the Forgot Password page. 2. Enter username: afram. 3. Click 'Reset Password' button. 4. Immediately click 'Reset Password' again (within ~500ms). 5. Observe button state during processing. 6. Check server for duplicate reset requests. | L21: Reset Password' button is disabled immediately after first click. Loading state (spinner) is shown. Only one reset request is sent to the server. | M21: Reset Password button remains enabled and clickable throughout processing. Multiple clicks send duplicate reset requests. No loading state is displayed. | O21: Open
